[2025-07-18T09:44:10.125+0000] {local_task_job_runner.py:120} INFO - ::group::Pre task execution logs
[2025-07-18T09:44:10.430+0000] {taskinstance.py:2076} INFO - Dependencies all met for dep_context=non-requeueable deps ti=<TaskInstance: ecommerce_etl.run_etl manual__2025-07-18T09:43:28.458630+00:00 [queued]>
[2025-07-18T09:44:10.460+0000] {taskinstance.py:2076} INFO - Dependencies all met for dep_context=requeueable deps ti=<TaskInstance: ecommerce_etl.run_etl manual__2025-07-18T09:43:28.458630+00:00 [queued]>
[2025-07-18T09:44:10.464+0000] {taskinstance.py:2306} INFO - Starting attempt 1 of 1
[2025-07-18T09:44:10.533+0000] {taskinstance.py:2330} INFO - Executing <Task(PythonOperator): run_etl> on 2025-07-18 09:43:28.458630+00:00
[2025-07-18T09:44:10.566+0000] {standard_task_runner.py:63} INFO - Started process 22348 to run task
[2025-07-18T09:44:10.572+0000] {standard_task_runner.py:90} INFO - Running: ['airflow', 'tasks', 'run', 'ecommerce_etl', 'run_etl', 'manual__2025-07-18T09:43:28.458630+00:00', '--job-id', '32', '--raw', '--subdir', 'DAGS_FOLDER/ecommerce_etl_dag.py', '--cfg-path', '/tmp/tmpybpqhkip']
[2025-07-18T09:44:10.578+0000] {standard_task_runner.py:91} INFO - Job 32: Subtask run_etl
[2025-07-18T09:44:10.799+0000] {task_command.py:426} INFO - Running <TaskInstance: ecommerce_etl.run_etl manual__2025-07-18T09:43:28.458630+00:00 [running]> on host LAPTOP-2CRA05LG.
[2025-07-18T09:44:11.165+0000] {taskinstance.py:2648} INFO - Exporting env vars: AIRFLOW_CTX_DAG_OWNER='airflow' AIRFLOW_CTX_DAG_ID='ecommerce_etl' AIRFLOW_CTX_TASK_ID='run_etl' AIRFLOW_CTX_EXECUTION_DATE='2025-07-18T09:43:28.458630+00:00' AIRFLOW_CTX_TRY_NUMBER='1' AIRFLOW_CTX_DAG_RUN_ID='manual__2025-07-18T09:43:28.458630+00:00'
[2025-07-18T09:44:11.169+0000] {taskinstance.py:430} INFO - ::endgroup::
[2025-07-18T09:44:11.671+0000] {logging_mixin.py:188} INFO - Creating SparkSession with appName: EcommerceSalesAnalytics and master: local[*]
[2025-07-18T09:44:37.339+0000] {logging_mixin.py:188} INFO - SparkSession created successfully.
[2025-07-18T09:44:37.342+0000] {logging_mixin.py:188} INFO - Attempting to read from: /mnt/c/Users/Shivam Gupta/OneDrive/Documents/Shivam_Developement/data_engineering/data_engineering_project/batch-etl-pyspark/data/raw/orders.csv
[2025-07-18T09:44:53.996+0000] {logging_mixin.py:188} INFO - Attempting to read from: /mnt/c/Users/Shivam Gupta/OneDrive/Documents/Shivam_Developement/data_engineering/data_engineering_project/batch-etl-pyspark/data/raw/customers.csv
[2025-07-18T09:44:54.629+0000] {logging_mixin.py:188} INFO - Attempting to read from: /mnt/c/Users/Shivam Gupta/OneDrive/Documents/Shivam_Developement/data_engineering/data_engineering_project/batch-etl-pyspark/data/raw/products.csv
[2025-07-18T09:44:55.311+0000] {logging_mixin.py:188} INFO - Attempting to write to: /mnt/c/Users/Shivam.../output/
[2025-07-18T09:44:56.572+0000] {taskinstance.py:441} INFO - ::group::Post task execution logs
[2025-07-18T09:44:56.578+0000] {taskinstance.py:2905} ERROR - Task failed with exception
Traceback (most recent call last):
  File "/mnt/c/Users/Shivam Gupta/OneDrive/Documents/Shivam_Developement/DATA_ENGINEERING/data_engineering_project/batch-etl-pyspark/.venv/lib/python3.12/site-packages/airflow/models/taskinstance.py", line 465, in _execute_task
    result = _execute_callable(context=context, **execute_callable_kwargs)
             ^^^^^^^^^^^^^^^^^^^^^^^^^^^^^^^^^^^^^^^^^^^^^^^^^^^^^^^^^^^^^
  File "/mnt/c/Users/Shivam Gupta/OneDrive/Documents/Shivam_Developement/DATA_ENGINEERING/data_engineering_project/batch-etl-pyspark/.venv/lib/python3.12/site-packages/airflow/models/taskinstance.py", line 432, in _execute_callable
    return execute_callable(context=context, **execute_callable_kwargs)
           ^^^^^^^^^^^^^^^^^^^^^^^^^^^^^^^^^^^^^^^^^^^^^^^^^^^^^^^^^^^^
  File "/mnt/c/Users/Shivam Gupta/OneDrive/Documents/Shivam_Developement/DATA_ENGINEERING/data_engineering_project/batch-etl-pyspark/.venv/lib/python3.12/site-packages/airflow/models/baseoperator.py", line 400, in wrapper
    return func(self, *args, **kwargs)
           ^^^^^^^^^^^^^^^^^^^^^^^^^^^
  File "/mnt/c/Users/Shivam Gupta/OneDrive/Documents/Shivam_Developement/DATA_ENGINEERING/data_engineering_project/batch-etl-pyspark/.venv/lib/python3.12/site-packages/airflow/operators/python.py", line 235, in execute
    return_value = self.execute_callable()
                   ^^^^^^^^^^^^^^^^^^^^^^^
  File "/mnt/c/Users/Shivam Gupta/OneDrive/Documents/Shivam_Developement/DATA_ENGINEERING/data_engineering_project/batch-etl-pyspark/.venv/lib/python3.12/site-packages/airflow/operators/python.py", line 252, in execute_callable
    return self.python_callable(*self.op_args, **self.op_kwargs)
           ^^^^^^^^^^^^^^^^^^^^^^^^^^^^^^^^^^^^^^^^^^^^^^^^^^^^^
  File "/mnt/c/Users/Shivam Gupta/OneDrive/Documents/Shivam_Developement/data_engineering/data_engineering_project/batch-etl-pyspark/airflow/dags/ecommerce_etl_dag.py", line 34, in run_etl
    write_output(enriched_df, output_path)
  File "/mnt/c/Users/Shivam Gupta/OneDrive/Documents/Shivam_Developement/data_engineering/data_engineering_project/batch-etl-pyspark/src/etl/load.py", line 13, in write_output
    df.write.format(output_format).mode(mode).save(output_path)
  File "/mnt/c/Users/Shivam Gupta/OneDrive/Documents/Shivam_Developement/DATA_ENGINEERING/data_engineering_project/batch-etl-pyspark/.venv/lib/python3.12/site-packages/pyspark/sql/readwriter.py", line 1463, in save
    self._jwrite.save(path)
  File "/mnt/c/Users/Shivam Gupta/OneDrive/Documents/Shivam_Developement/DATA_ENGINEERING/data_engineering_project/batch-etl-pyspark/.venv/lib/python3.12/site-packages/py4j/java_gateway.py", line 1322, in __call__
    return_value = get_return_value(
                   ^^^^^^^^^^^^^^^^^
  File "/mnt/c/Users/Shivam Gupta/OneDrive/Documents/Shivam_Developement/DATA_ENGINEERING/data_engineering_project/batch-etl-pyspark/.venv/lib/python3.12/site-packages/pyspark/errors/exceptions/captured.py", line 185, in deco
    raise converted from None
pyspark.errors.exceptions.captured.AnalysisException: [COLUMN_ALREADY_EXISTS] The column `name` already exists. Consider to choose another name or rename the existing column.
[2025-07-18T09:44:56.935+0000] {taskinstance.py:1206} INFO - Marking task as FAILED. dag_id=ecommerce_etl, task_id=run_etl, run_id=manual__2025-07-18T09:43:28.458630+00:00, execution_date=20250718T094328, start_date=20250718T094410, end_date=20250718T094456
[2025-07-18T09:44:57.036+0000] {standard_task_runner.py:110} ERROR - Failed to execute job 32 for task run_etl ([COLUMN_ALREADY_EXISTS] The column `name` already exists. Consider to choose another name or rename the existing column.; 22348)
[2025-07-18T09:44:57.067+0000] {local_task_job_runner.py:240} INFO - Task exited with return code 1
[2025-07-18T09:44:57.122+0000] {taskinstance.py:3498} INFO - 0 downstream tasks scheduled from follow-on schedule check
[2025-07-18T09:44:57.134+0000] {local_task_job_runner.py:222} INFO - ::endgroup::
